Workbook

Sheet Impressoras
A1: CADASTRO DE IMPRESSORAS — IP, Nº DE SÉRIE E PIN
A2: Planilha reorganizada automaticamente a partir do arquivo original. Última atualização: ver célula ao lado.
A4: Nº | B4: Filial / Unidade | C4: Setor / Local | D4: Modelo da Impressora | E4: Nº de Série | F4: Endereço IP | G4: PIN / Observação | H4: Status | I4: Scanner Usuario | J4: Scanner Senha
A5: 1 | B5: Arinos | C5: ARINOS (BALCÂO FUNDO) | D5: P3015 | E5: BRCSG2706W | F5: 192.168.106.34 | G5: (verificar) | H5: =IF(OR(ISNUMBER(SEARCH("manual",F5)),ISNUMBER(SEARCH("usb",F5))),"Impressora local (USB)",IF(OR(E5="",ISNUMBER(SEARCH("verificar",E5))),"Verificar nº de série",IF(F5="","Sem IP cadastrado",IF(OR(ISNUMBER(SEARCH("verificar",G5)),ISNUMBER(SEARCH("pegar",G5))),"Verificar PIN",IF(G5="","PIN não informado","OK"))))) -> Verificar PIN
A6: 2 | B6: Arinos | C6: Abatedouro Arinos | D6: HP 1102 | H6: =IF(OR(ISNUMBER(SEARCH("manual",F6)),ISNUMBER(SEARCH("usb",F6))),"Impressora local (USB)",IF(OR(E6="",ISNUMBER(SEARCH("verificar",E6))),"Verificar nº de série",IF(F6="","Sem IP cadastrado",IF(OR(ISNUMBER(SEARCH("verificar",G6)),ISNUMBER(SEARCH("pegar",G6))),"Verificar PIN",IF(G6="","PIN não informado","OK"))))) -> Verificar nº de série
A7: 3 | B7: Arinos | C7: Arinos AGV | D7: HP 4103 Fdw | E7: BRBSS1D009 | F7: 192.168.106.40 | G7: 93845138 | H7: =IF(OR(ISNUMBER(SEARCH("manual",F7)),ISNUMBER(SEARCH("usb",F7))),"Impressora local (USB)",IF(OR(E7="",ISNUMBER(SEARCH("verificar",E7))),"Verificar nº de série",IF(F7="","Sem IP cadastrado",IF(OR(ISNUMBER(SEARCH("verificar",G7)),ISNUMBER(SEARCH("pegar",G7))),"Verificar PIN",IF(G7="","PIN não informado","OK"))))) -> OK
A8: 4 | B8: Arinos | C8: Arinos AGV Balcão | D8: HP 426 Fdw | F8: 192.168.106.34 | G8: (reserva) | H8: =IF(OR(ISNUMBER(SEARCH("manual",F8)),ISNUMBER(SEARCH("usb",F8))),"Impressora local (USB)",IF(OR(E8="",ISNUMBER(SEARCH("verificar",E8))),"Verificar nº de série",IF(F8="","Sem IP cadastrado",IF(OR(ISNUMBER(SEARCH("verificar",G8)),ISNUMBER(SEARCH("pegar",G8))),"Verificar PIN",IF(G8="","PIN não informado","OK"))))) -> Verificar nº de série
A9: 5 | B9: Arinos | C9: Arinos AGV normal 01 | D9: HP 4003 Dw | E9: BRBSR6P0FH | F9: 192.168.106.41 | G9: 65562957 | H9: =IF(OR(ISNUMBER(SEARCH("manual",F9)),ISNUMBER(SEARCH("usb",F9))),"Impressora local (USB)",IF(OR(E9="",ISNUMBER(SEARCH("verificar",E9))),"Verificar nº de série",IF(F9="","Sem IP cadastrado",IF(OR(ISNUMBER(SEARCH("verificar",G9)),ISNUMBER(SEARCH("pegar",G9))),"Verificar PIN",IF(G9="","PIN não informado","OK"))))) -> OK
A10: 6 | B10: Arinos | C10: Arinos AGV normal 02 | D10: HP 4003 Dw | E10: BRBSR6P0GK | F10: 192.168.106.42 | G10: 65640910 | H10: =IF(OR(ISNUMBER(SEARCH("manual",F10)),ISNUMBER(SEARCH("usb",F10))),"Impressora local (USB)",IF(OR(E10="",ISNUMBER(SEARCH("verificar",E10))),"Verificar nº de série",IF(F10="","Sem IP cadastrado",IF(OR(ISNUMBER(SEARCH("verificar",G10)),ISNUMBER(SEARCH("pegar",G10))),"Verificar PIN",IF(G10="","PIN não informado","OK"))))) -> OK
A11: 7 | B11: Arinos | C11: Arinos Mercado | D11: HP 4103 Fdw | E11: BRBSRD704C | F11: 192.168.106.35 | G11: Pegar PIN | H11: =IF(OR(ISNUMBER(SEARCH("manual",F11)),ISNUMBER(SEARCH("usb",F11))),"Impressora local (USB)",IF(OR(E11="",ISNUMBER(SEARCH("verificar",E11))),"Verificar nº de série",IF(F11="","Sem IP cadastrado",IF(OR(ISNUMBER(SEARCH("verificar",G11)),ISNUMBER(SEARCH("pegar",G11))),"Verificar PIN",IF(G11="","PIN não informado","OK"))))) -> Verificar PIN
A12: 8 | B12: Arinos | C12: Arinos agv reserva | D12: HP 3015 | E12: BRCSG2F011 | G12: (usa o ip da que tirou) | H12: =IF(OR(ISNUMBER(SEARCH("manual",F12)),ISNUMBER(SEARCH("usb",F12))),"Impressora local (USB)",IF(OR(E12="",ISNUMBER(SEARCH("verificar",E12))),"Verificar nº de série",IF(F12="","Sem IP cadastrado",IF(OR(ISNUMBER(SEARCH("verificar",G12)),ISNUMBER(SEARCH("pegar",G12))),"Verificar PIN",IF(G12="","PIN não informado","OK"))))) -> Sem IP cadastrado
A13: 9 | B13: Arinos | C13: Arinos – Posto caixa | D13: HP 4003 Dw | E13: BRBSQ7S0PN | F13: 192.168.116.36 | G13: 21660333 | H13: =IF(OR(ISNUMBER(SEARCH("manual",F13)),ISNUMBER(SEARCH("usb",F13))),"Impressora local (USB)",IF(OR(E13="",ISNUMBER(SEARCH("verificar",E13))),"Verificar nº de série",IF(F13="","Sem IP cadastrado",IF(OR(ISNUMBER(SEARCH("verificar",G13)),ISNUMBER(SEARCH("pegar",G13))),"Verificar PIN",IF(G13="","PIN não informado","OK"))))) -> OK
A14: 10 | B14: Arinos | C14: Arinos – posto contin... | D14: HP 4103 Fdw | E14: BRBSQ51041 | F14: 192.168.116.35 | G14: 04815061 | H14: =IF(OR(ISNUMBER(SEARCH("manual",F14)),ISNUMBER(SEARCH("usb",F14))),"Impressora local (USB)",IF(OR(E14="",ISNUMBER(SEARCH("verificar",E14))),"Verificar nº de série",IF(F14="","Sem IP cadastrado",IF(OR(ISNUMBER(SEARCH("verificar",G14)),ISNUMBER(SEARCH("pegar",G14))),"Verificar PIN",IF(G14="","PIN não informado","OK"))))) -> OK | I14: ARI-15808 | J14: PAR-15808
A15: 11 | B15: Bonfinópolis | C15: Bonfin AGV normal 01 | D15: HP 4103 Fdw | E15: BRBSR6P0D2 | F15: 192.168.119.36 | G15: 65485134 | H15: =IF(OR(ISNUMBER(SEARCH("manual",F15)),ISNUMBER(SEARCH("usb",F15))),"Impressora local (USB)",IF(OR(E15="",ISNUMBER(SEARCH("verificar",E15))),"Verificar nº de série",IF(F15="","Sem IP cadastrado",IF(OR(ISNUMBER(SEARCH("verificar",G15)),ISNUMBER(SEARCH("pegar",G15))),"Verificar PIN",IF(G15="","PIN não informado","OK"))))) -> OK
A16: 12 | B16: Bonfinópolis | C16: Bonfin AGV normal 02 | D16: HP 4003 | E16: BRBSS9T05H | F16: 192.168.119.37 | G16: verificar | H16: =IF(OR(ISNUMBER(SEARCH("manual",F16)),ISNUMBER(SEARCH("usb",F16))),"Impressora local (USB)",IF(OR(E16="",ISNUMBER(SEARCH("verificar",E16))),"Verificar nº de série",IF(F16="","Sem IP cadastrado",IF(OR(ISNUMBER(SEARCH("verificar",G16)),ISNUMBER(SEARCH("pegar",G16))),"Verificar PIN",IF(G16="","PIN não informado","OK"))))) -> Verificar PIN
A17: 13 | B17: Bonfinópolis | C17: Bonfinópolis Balcão Vendas | D17: HP 3015 | F17: 192.168.119.38 | G17: verificar | H17: =IF(OR(ISNUMBER(SEARCH("manual",F17)),ISNUMBER(SEARCH("usb",F17))),"Impressora local (USB)",IF(OR(E17="",ISNUMBER(SEARCH("verificar",E17))),"Verificar nº de série",IF(F17="","Sem IP cadastrado",IF(OR(ISNUMBER(SEARCH("verificar",G17)),ISNUMBER(SEARCH("pegar",G17))),"Verificar PIN",IF(G17="","PIN não informado","OK"))))) -> Verificar nº de série
A18: 14 | B18: Bonfinópolis | C18: Bonfinópolis Mesa Aline | D18: HP 426 Fdw | E18: PHB8J6VFWM | F18: 192.168.119.35 | G18: verificar | H18: =IF(OR(ISNUMBER(SEARCH("manual",F18)),ISNUMBER(SEARCH("usb",F18))),"Impressora local (USB)",IF(OR(E18="",ISNUMBER(SEARCH("verificar",E18))),"Verificar nº de série",IF(F18="","Sem IP cadastrado",IF(OR(ISNUMBER(SEARCH("verificar",G18)),ISNUMBER(SEARCH("pegar",G18))),"Verificar PIN",IF(G18="","PIN não informado","OK"))))) -> Verificar PIN
A19: 15 | B19: Brasilândia | C19: Brasilândia AGV balcão | D19: HP Pro 400 | E19: CNF8G4HDH3 | F19: 192.168.128.35 | G19: verificar | H19: =IF(OR(ISNUMBER(SEARCH("manual",F19)),ISNUMBER(SEARCH("usb",F19))),"Impressora local (USB)",IF(OR(E19="",ISNUMBER(SEARCH("verificar",E19))),"Verificar nº de série",IF(F19="","Sem IP cadastrado",IF(OR(ISNUMBER(SEARCH("verificar",G19)),ISNUMBER(SEARCH("pegar",G19))),"Verificar PIN",IF(G19="","PIN não informado","OK"))))) -> Verificar PIN
A20: 16 | B20: Brasilândia | C20: Brasilândia AGV normal 01 | D20: HP 4003 Dw | E20: BRBSR6P08X | F20: 192.168.128.36 | G20: 65229271 | H20: =IF(OR(ISNUMBER(SEARCH("manual",F20)),ISNUMBER(SEARCH("usb",F20))),"Impressora local (USB)",IF(OR(E20="",ISNUMBER(SEARCH("verificar",E20))),"Verificar nº de série",IF(F20="","Sem IP cadastrado",IF(OR(ISNUMBER(SEARCH("verificar",G20)),ISNUMBER(SEARCH("pegar",G20))),"Verificar PIN",IF(G20="","PIN não informado","OK"))))) -> OK
A21: 17 | B21: Brasilândia | C21: Brasilândia AGV normal 02 | D21: HP 4003 Dw | E21: BRBSR4X069 | F21: 192.168.128.37 | G21: 27660562 | H21: =IF(OR(ISNUMBER(SEARCH("manual",F21)),ISNUMBER(SEARCH("usb",F21))),"Impressora local (USB)",IF(OR(E21="",ISNUMBER(SEARCH("verificar",E21))),"Verificar nº de série",IF(F21="","Sem IP cadastrado",IF(OR(ISNUMBER(SEARCH("verificar",G21)),ISNUMBER(SEARCH("pegar",G21))),"Verificar PIN",IF(G21="","PIN não informado","OK"))))) -> OK
A22: 18 | B22: Brasilândia | C22: Brasilândia AGV reserva | D22: Hp 3015 | F22: 192.168.128.39 | H22: =IF(OR(ISNUMBER(SEARCH("manual",F22)),ISNUMBER(SEARCH("usb",F22))),"Impressora local (USB)",IF(OR(E22="",ISNUMBER(SEARCH("verificar",E22))),"Verificar nº de série",IF(F22="","Sem IP cadastrado",IF(OR(ISNUMBER(SEARCH("verificar",G22)),ISNUMBER(SEARCH("pegar",G22))),"Verificar PIN",IF(G22="","PIN não informado","OK"))))) -> Verificar nº de série
A23: 19 | B23: Buritis | C23: Buritis AGV Balcão | D23: HP 4103 Fdw | E23: BRBSSDM09R | F23: 192.168.125.31 | G23: 3615771 | H23: =IF(OR(ISNUMBER(SEARCH("manual",F23)),ISNUMBER(SEARCH("usb",F23))),"Impressora local (USB)",IF(OR(E23="",ISNUMBER(SEARCH("verificar",E23))),"Verificar nº de série",IF(F23="","Sem IP cadastrado",IF(OR(ISNUMBER(SEARCH("verificar",G23)),ISNUMBER(SEARCH("pegar",G23))),"Verificar PIN",IF(G23="","PIN não informado","OK"))))) -> OK
A24: 20 | B24: Buritis | C24: Buritis AGV Ilza | D24: HP Pro 428fdw | E24: BRDSQCF0F0 | F24: 192.168.125.30 | H24: =IF(OR(ISNUMBER(SEARCH("manual",F24)),ISNUMBER(SEARCH("usb",F24))),"Impressora local (USB)",IF(OR(E24="",ISNUMBER(SEARCH("verificar",E24))),"Verificar nº de série",IF(F24="","Sem IP cadastrado",IF(OR(ISNUMBER(SEARCH("verificar",G24)),ISNUMBER(SEARCH("pegar",G24))),"Verificar PIN",IF(G24="","PIN não informado","OK"))))) -> PIN não informado
A25: 21 | B25: Buritis | C25: Buritis AGV normal 01 | D25: HP 4003 Dw | E25: BRBSR6P080 | F25: 192.168.125.32 | G25: 65188125 | H25: =IF(OR(ISNUMBER(SEARCH("manual",F25)),ISNUMBER(SEARCH("usb",F25))),"Impressora local (USB)",IF(OR(E25="",ISNUMBER(SEARCH("verificar",E25))),"Verificar nº de série",IF(F25="","Sem IP cadastrado",IF(OR(ISNUMBER(SEARCH("verificar",G25)),ISNUMBER(SEARCH("pegar",G25))),"Verificar PIN",IF(G25="","PIN não informado","OK"))))) -> OK
A26: 22 | B26: Buritis | C26: Buritis AGV normal 02 | D26: HP 4003 Dw | E26: BRBSRBM096 | F26: 192.168.125.33 | G26: 65585930 | H26: =IF(OR(ISNUMBER(SEARCH("manual",F26)),ISNUMBER(SEARCH("usb",F26))),"Impressora local (USB)",IF(OR(E26="",ISNUMBER(SEARCH("verificar",E26))),"Verificar nº de série",IF(F26="","Sem IP cadastrado",IF(OR(ISNUMBER(SEARCH("verificar",G26)),ISNUMBER(SEARCH("pegar",G26))),"Verificar PIN",IF(G26="","PIN não informado","OK"))))) -> OK
A27: 23 | B27: Cabeceira Goias | C27: CAG_BALCAO | D27: HP 3015 | F27: 192.168.129.38 | G27: Balcão | H27: =IF(OR(ISNUMBER(SEARCH("manual",F27)),ISNUMBER(SEARCH("usb",F27))),"Impressora local (USB)",IF(OR(E27="",ISNUMBER(SEARCH("verificar",E27))),"Verificar nº de série",IF(F27="","Sem IP cadastrado",IF(OR(ISNUMBER(SEARCH("verificar",G27)),ISNUMBER(SEARCH("pegar",G27))),"Verificar PIN",IF(G27="","PIN não informado","OK"))))) -> Verificar nº de série
A28: 24 | B28: Cabeceira Goias | C28: CAG_ESCRITORIO | D28: HP 426 | E28: BRBSV4S0KB | F28: 192.168.129.36 | G28: 92216916 | H28: =IF(OR(ISNUMBER(SEARCH("manual",F28)),ISNUMBER(SEARCH("usb",F28))),"Impressora local (USB)",IF(OR(E28="",ISNUMBER(SEARCH("verificar",E28))),"Verificar nº de série",IF(F28="","Sem IP cadastrado",IF(OR(ISNUMBER(SEARCH("verificar",G28)),ISNUMBER(SEARCH("pegar",G28))),"Verificar PIN",IF(G28="","PIN não informado","OK"))))) -> OK
A29: 25 | B29: Cabeceira Goias | C29: CAG_NORMAL01 | D29: HP 4003 Fdw | E29: BRBS07S0P0 | F29: 192.168.129.39 | G29: 21652072 | H29: =IF(OR(ISNUMBER(SEARCH("manual",F29)),ISNUMBER(SEARCH("usb",F29))),"Impressora local (USB)",IF(OR(E29="",ISNUMBER(SEARCH("verificar",E29))),"Verificar nº de série",IF(F29="","Sem IP cadastrado",IF(OR(ISNUMBER(SEARCH("verificar",G29)),ISNUMBER(SEARCH("pegar",G29))),"Verificar PIN",IF(G29="","PIN não informado","OK"))))) -> OK
A30: 26 | B30: Cabeceira Goias | C30: CAG_NORMAL02 | D30: HP 4003 Fdw | E30: BRBSR6P0G8 | F30: 192.168.129.40 | G30: 65628895 | H30: =IF(OR(ISNUMBER(SEARCH("manual",F30)),ISNUMBER(SEARCH("usb",F30))),"Impressora local (USB)",IF(OR(E30="",ISNUMBER(SEARCH("verificar",E30))),"Verificar nº de série",IF(F30="","Sem IP cadastrado",IF(OR(ISNUMBER(SEARCH("verificar",G30)),ISNUMBER(SEARCH("pegar",G30))),"Verificar PIN",IF(G30="","PIN não informado","OK"))))) -> OK
A31: 27 | B31: Cabeceira Goias | C31: CAG_RESERVA | D31: HP 4003 | E31: BRBSR6P0G5 | F31: 192.168.129.37 | G31: 65606446 | H31: =IF(OR(ISNUMBER(SEARCH("manual",F31)),ISNUMBER(SEARCH("usb",F31))),"Impressora local (USB)",IF(OR(E31="",ISNUMBER(SEARCH("verificar",E31))),"Verificar nº de série",IF(F31="","Sem IP cadastrado",IF(OR(ISNUMBER(SEARCH("verificar",G31)),ISNUMBER(SEARCH("pegar",G31))),"Verificar PIN",IF(G31="","PIN não informado","OK"))))) -> OK
A32: 28 | B32: Cabeceira Grande | C32: Cab Grande | D32: HP 428 Fdw | E32: BRDSQDF0FS | F32: 192.168.112.35 | H32: =IF(OR(ISNUMBER(SEARCH("manual",F32)),ISNUMBER(SEARCH("usb",F32))),"Impressora local (USB)",IF(OR(E32="",ISNUMBER(SEARCH("verificar",E32))),"Verificar nº de série",IF(F32="","Sem IP cadastrado",IF(OR(ISNUMBER(SEARCH("verificar",G32)),ISNUMBER(SEARCH("pegar",G32))),"Verificar PIN",IF(G32="","PIN não informado","OK"))))) -> PIN não informado
A33: 29 | B33: Cabeceira Grande | C33: Cab Grande AGV Continge. | D33: HP 4003 Dw | E33: BRBSR6P0FP | F33: 192.168.112.37 | G33: 65573020 | H33: =IF(OR(ISNUMBER(SEARCH("manual",F33)),ISNUMBER(SEARCH("usb",F33))),"Impressora local (USB)",IF(OR(E33="",ISNUMBER(SEARCH("verificar",E33))),"Verificar nº de série",IF(F33="","Sem IP cadastrado",IF(OR(ISNUMBER(SEARCH("verificar",G33)),ISNUMBER(SEARCH("pegar",G33))),"Verificar PIN",IF(G33="","PIN não informado","OK"))))) -> OK
A34: 30 | B34: Cabeceira Grande | C34: Cab Grande AGV normal | D34: HP 4003 Dw | E34: BRBSR6P09F | F34: 192.168.112.36 | G34: 65301488 | H34: =IF(OR(ISNUMBER(SEARCH("manual",F34)),ISNUMBER(SEARCH("usb",F34))),"Impressora local (USB)",IF(OR(E34="",ISNUMBER(SEARCH("verificar",E34))),"Verificar nº de série",IF(F34="","Sem IP cadastrado",IF(OR(ISNUMBER(SEARCH("verificar",G34)),ISNUMBER(SEARCH("pegar",G34))),"Verificar PIN",IF(G34="","PIN não informado","OK"))))) -> OK
A35: 31 | B35: Cabeceira Grande | C35: Cabeceira Grande (BALCÃO FUNDO) | D35: P3015 | E35: BRBSD6CK3H | F35: 192.168.112.56 | G35: (verificar) | H35: =IF(OR(ISNUMBER(SEARCH("manual",F35)),ISNUMBER(SEARCH("usb",F35))),"Impressora local (USB)",IF(OR(E35="",ISNUMBER(SEARCH("verificar",E35))),"Verificar nº de série",IF(F35="","Sem IP cadastrado",IF(OR(ISNUMBER(SEARCH("verificar",G35)),ISNUMBER(SEARCH("pegar",G35))),"Verificar PIN",IF(G35="","PIN não informado","OK"))))) -> Verificar PIN
A36: 32 | B36: Chapada | C36: Chapada BALCAO FUNDO | D36: HP P3015 | E36: BRBHC3B70G | F36: 192.168.152.36 | H36: =IF(OR(ISNUMBER(SEARCH("manual",F36)),ISNUMBER(SEARCH("usb",F36))),"Impressora local (USB)",IF(OR(E36="",ISNUMBER(SEARCH("verificar",E36))),"Verificar nº de série",IF(F36="","Sem IP cadastrado",IF(OR(ISNUMBER(SEARCH("verificar",G36)),ISNUMBER(SEARCH("pegar",G36))),"Verificar PIN",IF(G36="","PIN não informado","OK"))))) -> PIN não informado
A37: 33 | B37: Chapada | C37: Chapada CHA_NORMAL01 | D37: HP 4003 | E37: BRBSSDL00Q | F37: 192.168.152.35 | H37: =IF(OR(ISNUMBER(SEARCH("manual",F37)),ISNUMBER(SEARCH("usb",F37))),"Impressora local (USB)",IF(OR(E37="",ISNUMBER(SEARCH("verificar",E37))),"Verificar nº de série",IF(F37="","Sem IP cadastrado",IF(OR(ISNUMBER(SEARCH("verificar",G37)),ISNUMBER(SEARCH("pegar",G37))),"Verificar PIN",IF(G37="","PIN não informado","OK"))))) -> PIN não informado
A38: 34 | B38: Chapada | C38: Chapada ESCRITÓRIO | D38: HP M26 | E38: CNF8G6J60X | F38: 192.168.152.34 | H38: =IF(OR(ISNUMBER(SEARCH("manual",F38)),ISNUMBER(SEARCH("usb",F38))),"Impressora local (USB)",IF(OR(E38="",ISNUMBER(SEARCH("verificar",E38))),"Verificar nº de série",IF(F38="","Sem IP cadastrado",IF(OR(ISNUMBER(SEARCH("verificar",G38)),ISNUMBER(SEARCH("pegar",G38))),"Verificar PIN",IF(G38="","PIN não informado","OK"))))) -> PIN não informado
A39: 35 | B39: Chapada | C39: Chapada RESERVA | D39: HP P3015 | E39: BRBHB3R73L | F39: 192.168.152.37 | H39: =IF(OR(ISNUMBER(SEARCH("manual",F39)),ISNUMBER(SEARCH("usb",F39))),"Impressora local (USB)",IF(OR(E39="",ISNUMBER(SEARCH("verificar",E39))),"Verificar nº de série",IF(F39="","Sem IP cadastrado",IF(OR(ISNUMBER(SEARCH("verificar",G39)),ISNUMBER(SEARCH("pegar",G39))),"Verificar PIN",IF(G39="","PIN não informado","OK"))))) -> PIN não informado
A40: 36 | B40: Dom Bosco | C40: Dom Bosco AGV Contig | D40: HP 4003Dw | E40: BRBSR6P0FP | F40: 192.168.112.37 | G40: Verificar | H40: =IF(OR(ISNUMBER(SEARCH("manual",F40)),ISNUMBER(SEARCH("usb",F40))),"Impressora local (USB)",IF(OR(E40="",ISNUMBER(SEARCH("verificar",E40))),"Verificar nº de série",IF(F40="","Sem IP cadastrado",IF(OR(ISNUMBER(SEARCH("verificar",G40)),ISNUMBER(SEARCH("pegar",G40))),"Verificar PIN",IF(G40="","PIN não informado","OK"))))) -> Verificar PIN
A41: 37 | B41: Dom Bosco | C41: Dom Bosco Balcão agv | D41: HP 426 Fdw | E41: BRBSHBP6ZW | F41: 192.168.113.35 | H41: =IF(OR(ISNUMBER(SEARCH("manual",F41)),ISNUMBER(SEARCH("usb",F41))),"Impressora local (USB)",IF(OR(E41="",ISNUMBER(SEARCH("verificar",E41))),"Verificar nº de série",IF(F41="","Sem IP cadastrado",IF(OR(ISNUMBER(SEARCH("verificar",G41)),ISNUMBER(SEARCH("pegar",G41))),"Verificar PIN",IF(G41="","PIN não informado","OK"))))) -> PIN não informado
...

Sheet Dashboard
A1: PAINEL RESUMO
A3: Total de impressoras cadastradas | B3: =COUNTA(Impressoras!C5:C137) -> 133
A5: Filial / Unidade | B5: Qtde. de impressoras | C5: Sem IP | D5: A verificar
A6: Arinos | B6: =COUNTIF(Impressoras!$B$5:$B$137,A6) -> 10 | C6: =COUNTIFS(Impressoras!$B$5:$B$137,A6,Impressoras!$H$5:$H$137,"Sem IP cadastrado") -> 1 | D6: =COUNTIFS(Impressoras!$B$5:$B$137,A6,Impressoras!$H$5:$H$137,"Verificar*") -> 4
A7: Bonfinópolis | B7: =COUNTIF(Impressoras!$B$5:$B$137,A7) -> 4 | C7: =COUNTIFS(Impressoras!$B$5:$B$137,A7,Impressoras!$H$5:$H$137,"Sem IP cadastrado") -> 0 | D7: =COUNTIFS(Impressoras!$B$5:$B$137,A7,Impressoras!$H$5:$H$137,"Verificar*") -> 3
A8: Brasilândia | B8: =COUNTIF(Impressoras!$B$5:$B$137,A8) -> 4 | C8: =COUNTIFS(Impressoras!$B$5:$B$137,A8,Impressoras!$H$5:$H$137,"Sem IP cadastrado") -> 0 | D8: =COUNTIFS(Impressoras!$B$5:$B$137,A8,Impressoras!$H$5:$H$137,"Verificar*") -> 2
A9: Buritis | B9: =COUNTIF(Impressoras!$B$5:$B$137,A9) -> 4 | C9: =COUNTIFS(Impressoras!$B$5:$B$137,A9,Impressoras!$H$5:$H$137,"Sem IP cadastrado") -> 0 | D9: =COUNTIFS(Impressoras!$B$5:$B$137,A9,Impressoras!$H$5:$H$137,"Verificar*") -> 0
A10: Cabeceira Grande | B10: =COUNTIF(Impressoras!$B$5:$B$137,A10) -> 4 | C10: =COUNTIFS(Impressoras!$B$5:$B$137,A10,Impressoras!$H$5:$H$137,"Sem IP cadastrado") -> 0 | D10: =COUNTIFS(Impressoras!$B$5:$B$137,A10,Impressoras!$H$5:$H$137,"Verificar*") -> 1
A11: Chapada | B11: =COUNTIF(Impressoras!$B$5:$B$137,A11) -> 4 | C11: =COUNTIFS(Impressoras!$B$5:$B$137,A11,Impressoras!$H$5:$H$137,"Sem IP cadastrado") -> 0 | D11: =COUNTIFS(Impressoras!$B$5:$B$137,A11,Impressoras!$H$5:$H$137,"Verificar*") -> 0
A12: Dom Bosco | B12: =COUNTIF(Impressoras!$B$5:$B$137,A12) -> 4 | C12: =COUNTIFS(Impressoras!$B$5:$B$137,A12,Impressoras!$H$5:$H$137,"Sem IP cadastrado") -> 0 | D12: =COUNTIFS(Impressoras!$B$5:$B$137,A12,Impressoras!$H$5:$H$137,"Verificar*") -> 1
A13: Fábrica / Laticínios | B13: =COUNTIF(Impressoras!$B$5:$B$137,A13) -> 0 | C13: =COUNTIFS(Impressoras!$B$5:$B$137,A13,Impressoras!$H$5:$H$137,"Sem IP cadastrado") -> 0 | D13: =COUNTIFS(Impressoras!$B$5:$B$137,A13,Impressoras!$H$5:$H$137,"Verificar*") -> 0
A14: Natalândia | B14: =COUNTIF(Impressoras!$B$5:$B$137,A14) -> 3 | C14: =COUNTIFS(Impressoras!$B$5:$B$137,A14,Impressoras!$H$5:$H$137,"Sem IP cadastrado") -> 0 | D14: =COUNTIFS(Impressoras!$B$5:$B$137,A14,Impressoras!$H$5:$H$137,"Verificar*") -> 0
A15: Riachinho | B15: =COUNTIF(Impressoras!$B$5:$B$137,A15) -> 5 | C15: =COUNTIFS(Impressoras!$B$5:$B$137,A15,Impressoras!$H$5:$H$137,"Sem IP cadastrado") -> 0 | D15: =COUNTIFS(Impressoras!$B$5:$B$137,A15,Impressoras!$H$5:$H$137,"Verificar*") -> 1
A16: Rural Minas | B16: =COUNTIF(Impressoras!$B$5:$B$137,A16) -> 3 | C16: =COUNTIFS(Impressoras!$B$5:$B$137,A16,Impressoras!$H$5:$H$137,"Sem IP cadastrado") -> 0 | D16: =COUNTIFS(Impressoras!$B$5:$B$137,A16,Impressoras!$H$5:$H$137,"Verificar*") -> 0
A17: Unaí | B17: =COUNTIF(Impressoras!$B$5:$B$137,A17) -> 51 | C17: =COUNTIFS(Impressoras!$B$5:$B$137,A17,Impressoras!$H$5:$H$137,"Sem IP cadastrado") -> 1 | D17: =COUNTIFS(Impressoras!$B$5:$B$137,A17,Impressoras!$H$5:$H$137,"Verificar*") -> 1
... A20: Xingu Capul | B20: =COUNTIF(Impressoras!$B$5:$B$137,A20) -> 1 | C20: =COUNTIFS(Impressoras!$B$5:$B$137,A20,Impressoras!$H$5:$H$137,"Sem IP cadastrado") -> 0 | D20: =COUNTIFS(Impressoras!$B$5:$B$137,A20,Impressoras!$H$5:$H$137,"Verificar*") -> 0
A22: Status | B22: Quantidade
A23: OK | B23: =COUNTIF(Impressoras!$H$5:$H$137,A23) -> 43
A24: Sem IP cadastrado | B24: =COUNTIF(Impressoras!$H$5:$H$137,A24) -> 2
A25: Verificar nº de série | B25: =COUNTIF(Impressoras!$H$5:$H$137,A25) -> 9
A26: Verificar PIN | B26: =COUNTIF(Impressoras!$H$5:$H$137,A26) -> 9
A27: PIN não informado | B27: =COUNTIF(Impressoras!$H$5:$H$137,A27) -> 62
A28: Impressora local (USB) | B28: =COUNTIF(Impressoras!$H$5:$H$137,A28) -> 8

Sheet Como Automatizar
A1: COMO AUTOMATIZAR E TRANSFORMAR ISSO EM UM SITE
A3: 1. Padronize a coleta | B3: Sempre preencha Filial, Setor, Modelo, Nº de Série, IP e PIN. Sem esses 6 campos, nenhuma automação funciona bem.
A5: 2. Valide o IP automaticamente | B5: A coluna "Status" já usa fórmulas para sinalizar IP ausente, PIN pendente ou série a verificar. Não apague as fórmulas.
A7: 3. Monitoramento automático de impressoras | B7: Ferramentas como PRTG, Zabbix, LibreNMS ou PaperCut leem esta lista de IPs via SNMP e avisam quando uma impressora está offline, sem toner ou com erro de papel — sem precisar abrir a planilha.
A9: 4. Planilha -> Banco de dados | B9: Suba estes dados para Google Sheets (com Apps Script) ou para uma base como Airtable/Baserow. Isso permite consultar e editar de qualquer lugar, com histórico de alterações.
A11: 5. Virar um site simples | B11: Com o Google Sheets publicado, ferramentas como Glide, Softr ou AppSheet criam um site/app de consulta em minutos, sem programar — cada filial vê só as suas impressoras.
A13: 6. Site sob medida | B13: Se quiser algo mais robusto (login por filial, alertas automáticos, histórico de trocas de toner), dá para construir um pequeno sistema web (ex.: com banco de dados + painel) — posso te ajudar a montar isso também.
A15: 7. QR Code por impressora | B15: Gere um QR Code para cada impressora (com IP, modelo e PIN) e cole na própria máquina — o técnico escaneia e já vê os dados, sem precisar abrir a planilha.

Sheet Dados Originais (backup)
A1: Cópia integral dos dados originais, sem edições — apenas para consulta e conferência.
A3: Setor | B3: Modelo Impressora | C3: N° de série | D3: IP | E3: PIN
A4: Arinos AGV normal 01 | B4: HP 4003 Dw | C4: BRBSR6P0FH | D4: 192.168.106.41 | E4: 65562957
A5: Arinos AGV normal 02 | B5: HP 4003 Dw | C5: BRBSR6P0GK | D5: 192.168.106.42 | E5: 65640910
A6: Arinos AGV Balcão | B6: HP 426 Fdw | D6: 192.168.106.34 | E6: (reserva)
A7: Arinos agv reserva | B7: HP 3015 | C7: BRCSG2F011 | E7: (usa o ip da que tirou)
A8: Arinos Mercado | B8: HP 4103 Fdw | C8: BRBSRD704C | D8: 192.168.106.35 | E8: Pegar PIN
A9: Arinos – posto contin... | B9: HP 4103 Fdw | C9: BRBSQ51041 | D9: 192.168.116.35 | E9: 4815061
A10: Arinos – Posto caixa | B10: HP 4003 Dw | C10: BRBSQ7S0PN | D10: 192.168.116.36 | E10: 21660333
A11: Arinos AGV | B11: HP 4103 Fdw | C11: BRBSS1D009 | D11: 192.168.106.40 | E11: 93845138
A12: Bonfin AGV normal 01 | B12: HP 4103 Fdw | C12: BRBSR6P0D2 | D12: 192.168.119.36 | E12: 65485134
A13: Bonfin AGV normal 02 | B13: HP 4003 | C13: BRBSS9T05H | D13: 192.168.119.37 | E13: verificar
A14: Bonfinópolis Mesa Aline | B14: HP 426 Fdw | C14: PHB8J6VFWM | D14: 192.168.119.35 | E14: verificar
A15: Bonfinópolis Balcão Vendas | B15: HP 3015 | D15: 192.168.119.38 | E15: verificar
A16: Brasilândia AGV balcão | B16: HP Pro 400 | C16: CNF8G4HDH3 | D16: 192.168.128.35 | E16: verificar
A17: Brasilândia AGV normal 01 | B17: HP 4003 Dw | C17: BRBSR6P08X | D17: 192.168.128.36 | E17: 65229271
A18: Brasilândia AGV normal 02 | B18: HP 4003 Dw | C18: BRBSR4X069 | D18: 192.168.128.37 | E18: 27660562
A19: Brasilândia AGV reserva | B19: Hp 3015 | D19: 192.168.128.39
A20: Buritis AGV normal 01 | B20: HP 4003 Dw | C20: BRBSR6P080 | D20: 192.168.125.32 | E20: 65188125
A21: Buritis AGV normal 02 | B21: HP 4003 Dw | C21: BRBSRBM096 | D21: 192.168.125.33 | E21: 65585930
A22: Buritis AGV Balcão | B22: HP 4103 Fdw | C22: BRBSSDM09R | D22: 192.168.125.31 | E22: 3615771
A23: Buritis AGV Ilza | B23: HP Pro 428fdw | C23: BRDSQCF0F0 | D23: 192.168.125.30
A24: CAG_NORMAL02 | B24: HP 4003 Fdw | C24: BRBSR6P0G8 | D24: 192.168.129.40 | E24: 65628895
A25: CAG_NORMAL01 | B25: HP 4003 Fdw | C25: BRBS07S0P0 | D25: 192.168.129.39 | E25: 21652072
A26: CAG_BALCAO | B26: HP 3015 | D26: 192.168.129.38 | E26: Balcão
A27: CAG_RESERVA | B27: HP 4003 | D27: 192.168.129.37
A28: CAG_ESCRITORIO | B28: HP 426 | C28: BRBSV4S0KB | D28: 192.168.129.36 | E28: 92216916
A29: Cab Grande AGV Continge. | B29: HP 4003 Dw | C29: BRBSR6P0FP | D29: 192.168.112.37 | E29: 65573020
A30: Cab Grande AGV normal | B30: HP 4003 Dw | C30: BRBSR6P09F | D30: 192.168.112.36 | E30: 65301488
A31: Cab Grande | B31: HP 428 Fdw | C31: BRDSQDF0FS | D31: 192.168.112.35
A32: Chapada ESCRITÓRIO | B32: HP M26 | D32: 192.168.152.34
A33: Chapada CHA_NORMAL01 | B33: HP 4003 | D33: 192.168.152.35
A34: Chapada BALCAO FUNDO | B34: HP P3015 | D34: 192.168.152.36
A35: Chapada RESERVA | B35: HP P3015 | D35: 192.168.152.37
A36: Dom Bosco Balcão agv | B36: HP 426 Fdw | C36: BRBSHBP6ZW | D36: 192.168.113.35
A37: Dom Bosco AGV Contig | B37: HP 4003Dw | C37: BRBSR6P0FP | D37: 192.168.112.37 | E37: Verificar
A38: Dom Bosco Normal (caixa) | B38: HP 4003 Dw | C38: BRBSR6P0FK | D38: 192.168.113.36 | E38: 65564184
A39: Dom Bosco Mercado | B39: HP 4103 Dw | C39: BRBSRD7049 | D39: 192.168.113.38 | E39: 69947784
A40: Fabrica Almoxarifado | B40: HP 426 Fdw | C40: BRBSL6M321 | D40: 192.168.118.53
A41: Fabrica Laboratório | B41: HP Laser Jet Sun | C41: CNF8H4WHG2 | D41: 192.168.118.55
...
